<robot name="object">
  <link name="world" />
  <link name="object">
    <visual>
       <geometry>
	   <box size=".05 .03 .05"/>
	</geometry>
    </visual>
    <collision>
       <geometry>
           <box size=".05 .03 .05"/>
	</geometry>
    </collision>
    <inertial>
    	<mass value="0.05"/>
      <inertia ixx="0.0108" ixy="0" ixz="0" iyy="0.0083" iyz="0" izz="0.0042"/>
    </inertial>
  </link>

  <gazebo reference="object">
      <dampingFactor>0.005</dampingFactor>
      <kp>1000000</kp>
      <kd>1.0</kd>
      <mu1>100.0</mu1>
      <mu2>100.0</mu2>
      <minDepth>0.001</minDepth>
  </gazebo>
  <joint name="joint1" type="floating">
    <parent link="world"/>
    <child link="object"/>
  </joint>
</robot>
